Workbook
Name クラス情報: #REF!
Name クラス情報3: #REF!
Name クラス名: [1]クラスＩＤ11.4更新!$X$1:$Y$17
Name グレード: [1]クラスＩＤ11.4更新!$P$2:$Q$9
Name グレード2: [2]関数!$D$2:$E$8
Name これを印刷: #REF!
Name ブランド: [3]確認マシーン!$A$2:$A$14
Name ペアリレー: [2]関数!$C$2:$C$4
Name 丸: [2]関数!$A$2
Name 吉根校: #REF!
Name 月: [2]関数!$F$15:$F$26
Name 校舎: [1]クラスＩＤ11.4更新!$S$1:$U$52
Name 校舎名: [2]関数!$CK$2:$CK$57
Name 時給単価: [2]関数!$C$15
Name 時給内容: [2]関数!$A$34:$A$42
Name 授業時間: [2]関数!$E$2:$F$8
Name 授業時間2: [2]関数!$CI$2:$CI$158
Name 祝日リスト2022: '[4]21901 小学受験部 年少.年中 通期'!$M$2:$N$73
Name 出欠: [2]関数!$A$2:$A$4
Name 全部: #REF!
Name 待機1: [2]関数!#REF!
Name 待機2: [2]関数!#REF!
Name 待機3: [2]関数!#REF!
Name 待機4: [2]関数!#REF!
Name 待機5: [2]関数!#REF!
Name 待機6: [2]関数!#REF!
Name 待機No: [2]関数!#REF!
Name 日給: [2]関数!$J$2:$L$45
Name 日給単価: [2]関数!$A$15:$A$19
Name 日給内容: [2]関数!$A$27:$A$28
Name 年度: [2]関数!$E$15:$E$24
Name 尾張旭校: #REF!
Name 曜日: [2]関数!$CM$2:$CM$8

Sheet ②T11_ルーム情報_CSV書き出し用DATAもと
A1: =IF(③T11_ルーム情報!A1="","",③T11_ルーム情報!A1) -> OZA_ID | B1: =IF(③T11_ルーム情報!B1="","",③T11_ルーム情報!B1) -> 校舎ID | C1: =IF(③T11_ルーム情報!C1="","",③T11_ルーム情報!C1) -> 校舎名 | D1: =IF(③T11_ルーム情報!D1="","",③T11_ルーム情報!D1) -> ルーム名 | E1: =IF(③T11_ルーム情報!E1="","",③T11_ルーム情報!E1) -> 席数 | F1: =IF(③T11_ルーム情報!F1="","",③T11_ルーム情報!F1) -> 教室の説明
A2: =IF(③T11_ルーム情報!A2="","",③T11_ルーム情報!A2) | B2: =IF(③T11_ルーム情報!B2="","",③T11_ルーム情報!B2) -> S10001 | C2: =IF(③T11_ルーム情報!C2="","",③T11_ルーム情報!C2) -> 尾張旭校 | D2: =IF(③T11_ルーム情報!D2="","",③T11_ルーム情報!D2) -> ROOM1 | E2: =IF(③T11_ルーム情報!E2="","",③T11_ルーム情報!E2) -> 15 | F2: =IF(③T11_ルーム情報!F2="","",③T11_ルーム情報!F2) -> １F アン
A3: =IF(③T11_ルーム情報!A3="","",③T11_ルーム情報!A3) | B3: =IF(③T11_ルーム情報!B3="","",③T11_ルーム情報!B3) -> S10001 | C3: =IF(③T11_ルーム情報!C3="","",③T11_ルーム情報!C3) -> 尾張旭校 | D3: =IF(③T11_ルーム情報!D3="","",③T11_ルーム情報!D3) -> ROOM2 | E3: =IF(③T11_ルーム情報!E3="","",③T11_ルーム情報!E3) -> 8 | F3: =IF(③T11_ルーム情報!F3="","",③T11_ルーム情報!F3) -> １F 会議室大
A4: =IF(③T11_ルーム情報!A4="","",③T11_ルーム情報!A4) | B4: =IF(③T11_ルーム情報!B4="","",③T11_ルーム情報!B4) -> S10001 | C4: =IF(③T11_ルーム情報!C4="","",③T11_ルーム情報!C4) -> 尾張旭校 | D4: =IF(③T11_ルーム情報!D4="","",③T11_ルーム情報!D4) -> ROOM3 | E4: =IF(③T11_ルーム情報!E4="","",③T11_ルーム情報!E4) -> 5 | F4: =IF(③T11_ルーム情報!F4="","",③T11_ルーム情報!F4) -> １F 会議室小
A5: =IF(③T11_ルーム情報!A5="","",③T11_ルーム情報!A5) | B5: =IF(③T11_ルーム情報!B5="","",③T11_ルーム情報!B5) -> S10001 | C5: =IF(③T11_ルーム情報!C5="","",③T11_ルーム情報!C5) -> 尾張旭校 | D5: =IF(③T11_ルーム情報!D5="","",③T11_ルーム情報!D5) -> ROOM4 | E5: =IF(③T11_ルーム情報!E5="","",③T11_ルーム情報!E5) -> 36 | F5: =IF(③T11_ルーム情報!F5="","",③T11_ルーム情報!F5) -> ２F 塾部屋
A6: =IF(③T11_ルーム情報!A6="","",③T11_ルーム情報!A6) | B6: =IF(③T11_ルーム情報!B6="","",③T11_ルーム情報!B6) -> S10001 | C6: =IF(③T11_ルーム情報!C6="","",③T11_ルーム情報!C6) -> 尾張旭校 | D6: =IF(③T11_ルーム情報!D6="","",③T11_ルーム情報!D6) -> ROOM5 | E6: =IF(③T11_ルーム情報!E6="","",③T11_ルーム情報!E6) -> 30 | F6: =IF(③T11_ルーム情報!F6="","",③T11_ルーム情報!F6) -> ２F そろばん/習字
A7: =IF(③T11_ルーム情報!A7="","",③T11_ルーム情報!A7) | B7: =IF(③T11_ルーム情報!B7="","",③T11_ルーム情報!B7) -> S10001 | C7: =IF(③T11_ルーム情報!C7="","",③T11_ルーム情報!C7) -> 尾張旭校 | D7: =IF(③T11_ルーム情報!D7="","",③T11_ルーム情報!D7) -> ROOM6 | E7: =IF(③T11_ルーム情報!E7="","",③T11_ルーム情報!E7) -> 5 | F7: =IF(③T11_ルーム情報!F7="","",③T11_ルーム情報!F7) -> ２F 応接/中受験
A8: =IF(③T11_ルーム情報!A8="","",③T11_ルーム情報!A8) | B8: =IF(③T11_ルーム情報!B8="","",③T11_ルーム情報!B8) -> S10001 | C8: =IF(③T11_ルーム情報!C8="","",③T11_ルーム情報!C8) -> 尾張旭校 | D8: =IF(③T11_ルーム情報!D8="","",③T11_ルーム情報!D8) -> ROOM7 | E8: =IF(③T11_ルーム情報!E8="","",③T11_ルーム情報!E8) -> 6 | F8: =IF(③T11_ルーム情報!F8="","",③T11_ルーム情報!F8) -> ２F 中入研倉庫
A9: =IF(③T11_ルーム情報!A9="","",③T11_ルーム情報!A9) | B9: =IF(③T11_ルーム情報!B9="","",③T11_ルーム情報!B9) -> S10002 | C9: =IF(③T11_ルーム情報!C9="","",③T11_ルーム情報!C9) -> 吉根校 | D9: =IF(③T11_ルーム情報!D9="","",③T11_ルーム情報!D9) -> ROOM1 | E9: =IF(③T11_ルーム情報!E9="","",③T11_ルーム情報!E9) -> 13 | F9: =IF(③T11_ルーム情報!F9="","",③T11_ルーム情報!F9) -> １F アン
A10: =IF(③T11_ルーム情報!A10="","",③T11_ルーム情報!A10) | B10: =IF(③T11_ルーム情報!B10="","",③T11_ルーム情報!B10) -> S10002 | C10: =IF(③T11_ルーム情報!C10="","",③T11_ルーム情報!C10) -> 吉根校 | D10: =IF(③T11_ルーム情報!D10="","",③T11_ルーム情報!D10) -> ROOM2 | E10: =IF(③T11_ルーム情報!E10="","",③T11_ルーム情報!E10) -> 12 | F10: =IF(③T11_ルーム情報!F10="","",③T11_ルーム情報!F10) -> ２F そろばん/習字
A11: =IF(③T11_ルーム情報!A11="","",③T11_ルーム情報!A11) | B11: =IF(③T11_ルーム情報!B11="","",③T11_ルーム情報!B11) -> S10003 | C11: =IF(③T11_ルーム情報!C11="","",③T11_ルーム情報!C11) -> 小幡校 | D11: =IF(③T11_ルーム情報!D11="","",③T11_ルーム情報!D11) -> ROOM1 | E11: =IF(③T11_ルーム情報!E11="","",③T11_ルーム情報!E11) -> 14 | F11: =IF(③T11_ルーム情報!F11="","",③T11_ルーム情報!F11) -> 1Fそろばん習字
A12: =IF(③T11_ルーム情報!A12="","",③T11_ルーム情報!A12) | B12: =IF(③T11_ルーム情報!B12="","",③T11_ルーム情報!B12) -> S10003 | C12: =IF(③T11_ルーム情報!C12="","",③T11_ルーム情報!C12) -> 小幡校 | D12: =IF(③T11_ルーム情報!D12="","",③T11_ルーム情報!D12) -> ROOM2 | E12: =IF(③T11_ルーム情報!E12="","",③T11_ルーム情報!E12) -> 15 | F12: =IF(③T11_ルーム情報!F12="","",③T11_ルーム情報!F12) -> 2F アン部屋
... A260: =IF(③T11_ルーム情報!A260="","",③T11_ルーム情報!A260) | B260: =IF(③T11_ルーム情報!B260="","",③T11_ルーム情報!B260) | C260: =IF(③T11_ルーム情報!C260="","",③T11_ルーム情報!C260) | D260: =IF(③T11_ルーム情報!D260="","",③T11_ルーム情報!D260) | E260: =IF(③T11_ルーム情報!E260="","",③T11_ルーム情報!E260) | F260: =IF(③T11_ルーム情報!F260="","",③T11_ルーム情報!F260)

Sheet ③T11_ルーム情報
A1: OZA_ID | B1: 校舎ID | C1: 校舎名 | D1: ルーム名 | E1: 席数 | F1: 教室の説明 | J1: 校舎ID | K1: 校舎名 | L1: 校舎ローマ字名 | M1: 短縮名 | N1: 部屋数 | O1: 校舎ID | Q1: アン | R1: そろ | S1: 習字 | T1: さんこく | U1: プログラミング | V1: ガクセン | W1: 光の泉 | X1: 本科 | Y1: 山の手 | Z1: キタン文理
B2: S10001 | C2: 尾張旭校 | D2: ROOM1 | E2: 15 | F2: １F アン | H2: =COUNTIF($B:$B,J2) -> 7 | I2: =IF(H2=N2,"〇","×") -> 〇 | J2: S10001 | K2: 尾張旭校 | L2: Owariasahi | M2: 尾張旭 | N2: 7 | O2: S10001 | Q2: ●
B3: S10001 | C3: 尾張旭校 | D3: ROOM2 | E3: 8 | F3: １F 会議室大 | H3: =COUNTIF($B:$B,J3) -> 2 | I3: =IF(H3=N3,"〇","×") -> 〇 | J3: S10002 | K3: 吉根校 | L3: Kikko | M3: 吉根校 | N3: 2 | O3: S10002
B4: S10001 | C4: 尾張旭校 | D4: ROOM3 | E4: 5 | F4: １F 会議室小 | H4: =COUNTIF($B:$B,J4) -> 3 | I4: =IF(H4=N4,"〇","×") -> 〇 | J4: S10003 | K4: 小幡校 | L4: Obata | M4: 小幡校 | N4: 3 | O4: S10003
B5: S10001 | C5: 尾張旭校 | D5: ROOM4 | E5: 36 | F5: ２F 塾部屋 | H5: =COUNTIF($B:$B,J5) -> 3 | I5: =IF(H5=N5,"〇","×") -> 〇 | J5: S10004 | K5: 喜多山校 | L5: Kitayama | M5: 喜多山 | N5: 3 | O5: S10004
B6: S10001 | C6: 尾張旭校 | D6: ROOM5 | E6: 30 | F6: ２F そろばん/習字 | H6: =COUNTIF($B:$B,J6) -> 2 | I6: =IF(H6=N6,"〇","×") -> 〇 | J6: S10006 | K6: 本山校 | L6: Motoyama | M6: 本山校 | N6: 2 | O6: S10006
B7: S10001 | C7: 尾張旭校 | D7: ROOM6 | E7: 5 | F7: ２F 応接/中受験 | H7: =COUNTIF($B:$B,J7) -> 1 | I7: =IF(H7=N7,"〇","×") -> 〇 | J7: S10007 | K7: 千種谷口校 | L7: Taniguchi | M7: 谷口校 | N7: 1 | O7: S10007
B8: S10001 | C8: 尾張旭校 | D8: ROOM7 | E8: 6 | F8: ２F 中入研倉庫 | H8: =COUNTIF($B:$B,J8) -> 7 | I8: =IF(H8=N8,"〇","×") -> 〇 | J8: S10008 | K8: 千種本部校 | L8: Chikusa | M8: 千種本 | N8: 7 | O8: S10008
B9: S10002 | C9: 吉根校 | D9: ROOM1 | E9: 13 | F9: １F アン | H9: =COUNTIF($B:$B,J9) -> 2 | I9: =IF(H9=N9,"〇","×") -> 〇 | J9: S10009 | K9: 豊明三崎校 | L9: Toyoake | M9: 豊明三 | N9: 2 | O9: S10009
B10: S10002 | C10: 吉根校 | D10: ROOM2 | E10: 12 | F10: ２F そろばん/習字 | H10: =COUNTIF($B:$B,J10) -> 2 | I10: =IF(H10=N10,"〇","×") -> 〇 | J10: S10010 | K10: 三郷校 | L10: Sango | M10: 三郷校 | N10: 2 | O10: S10010
B11: S10003 | C11: 小幡校 | D11: ROOM1 | E11: 14 | F11: 1Fそろばん習字 | H11: =COUNTIF($B:$B,J11) -> 3 | I11: =IF(H11=N11,"〇","×") -> 〇 | J11: S10011 | K11: 瀬戸山口校 | L11: Yamaguchi | M11: 瀬戸山 | N11: 3 | O11: S10011
B12: S10003 | C12: 小幡校 | D12: ROOM2 | E12: 15 | F12: 2F アン部屋 | H12: =COUNTIF($B:$B,J12) -> 3 | I12: =IF(H12=N12,"〇","×") -> 〇 | J12: S10012 | K12: 四軒家校 | L12: Shikenya | M12: 四軒家 | N12: 3 | O12: S10012
B13: S10003 | C13: 小幡校 | D13: ROOM3 | E13: 28 | F13: 2F 塾部屋 | H13: =COUNTIF($B:$B,J13) -> 2 | I13: =IF(H13=N13,"〇","×") -> 〇 | J13: S10013 | K13: 新守山校 | L13: Shinmori | M13: 新守山 | N13: 2 | O13: S10013
B14: S10004 | C14: 喜多山校 | D14: ROOM1 | E14: 20 | F14: アン部屋 | H14: =COUNTIF($B:$B,J14) -> 2 | I14: =IF(H14=N14,"〇","×") -> 〇 | J14: S10016 | K14: 甚目寺校 | L14: Jimokuji | M14: 甚目寺 | N14: 2 | O14: S10016
... B69: S10031 | C69: 蟹江校 | D69: ROOM1 | E69: 14 | F69: アン/そろ | H69: =COUNTIF($B:$B,J69) -> 5 | I69: =IF(H69=N69,"〇","×") -> 〇 | J69: S10170 | K69: 笠松校 | L69: Kasamatsu | M69: 笠松校 | N69: 5 | O69: S10170
B70: S10032 | C70: 清洲校 | D70: ROOM1 | E70: 20 | F70: アン/そろ
B71: S10034 | C71: 東郷校 | D71: ROOM1 | E71: 17 | F71: アン
B72: S10034 | C72: 東郷校 | D72: ROOM2 | E72: 9 | F72: そろばん
B73: S10035 | C73: 丸一校 | D73: ROOM1 | E73: 14 | F73: 1Fアン
B74: S10035 | C74: 丸一校 | D74: ROOM2 | E74: 28 | F74: 2Fそろばん習字
B75: S10035 | C75: 丸一校 | D75: ROOM3 | E75: 25 | F75: 2F塾
B76: S10037 | C76: 扶桑校 | D76: ROOM1 | E76: 15 | F76: アン
B77: S10037 | C77: 扶桑校 | D77: ROOM2 | E77: 15 | F77: そろばん習字
B78: S10038 | C78: 野並校 | D78: ROOM1 | E78: 17 | F78: アン/そろ
B79: S10039 | C79: 愛西本部校 | D79: ROOM1 | E79: 34 | F79: 学習塾
B80: S10039 | C80: 愛西本部校 | D80: ROOM2 | E80: 12 | F80: 英語
B81: S10039 | C81: 愛西本部校 | D81: ROOM3 | E81: 16 | F81: そろばん
... B196: S10172 | C196: 光の泉本校 | D196: Room13 | E196: 8 | F196: 6F-2
B197: S10168 | C197: 長良校 | D197: Room1 | E197: 17 | F197: 2F奥 | H197: =COUNTIF($B:$B,J197) -> 3 | I197: =IF(H197=N197,"〇","×") -> 〇 | J197: S10167 | K197: 長良高校前校 | L197: Nagara | M197: 長良高 | N197: 3 | O197: S10167
B198: S10168 | C198: 長良校 | D198: Room2 | E198: 14 | F198: 2Fオープン | H198: =COUNTIF($B:$B,J198) -> 5 | I198: =IF(H198=N198,"〇","×") -> 〇 | J198: S10169 | K198: 三里校 | L198: Misato | M198: 三里校 | N198: 5 | O198: S10169
B199: S10168 | C199: 長良校 | D199: Room3 | E199: 10 | F199: 2F旧アニー部屋 | H199: =COUNTIF($B:$B,J199) -> 14 | I199: =IF(H199=N199,"〇","×") -> 〇 | J199: S10168 | K199: 長良校 | L199: Nagarakou | M199: 長良校 | N199: 14 | O199: S10168
B200: S10168 | C200: 長良校 | D200: Room4 | E200: 31 | F200: 2F自習ブース | H200: =COUNTIF($B:$B,J200) -> 14 | I200: =IF(H200=N200,"〇","×") -> 〇 | J200: S10173 | K200: 光の泉北校 | L200: Hikarinoizumikita | M200: 泉北校 | N200: 14 | O200: S10173
B201: S10168 | C201: 長良校 | D201: Room5 | E201: 2 | F201: 2F山の手① | H201: =COUNTIF($B:$B,J201) -> 13 | I201: =IF(H201=N201,"〇","×") -> 〇 | J201: S10172 | K201: 光の泉本校 | L201: Hikarinoizumihonkou | M201: 泉本校 | N201: 13 | O201: S10172
B202: S10168 | C202: 長良校 | D202: Room6 | E202: 4 | F202: 高校個別 | H202: =COUNTIF($B:$B,J202) -> 13 | I202: =IF(H202=N202,"〇","×") -> 〇 | J202: S10175 | K202: 岐阜駅南口校 | L202: Gifuekiminami | M202: 岐阜南 | N202: 13 | O202: S10175
B203: S10168 | C203: 長良校 | D203: Room7 | E203: 22 | F203: 3F1番 | H203: =COUNTIF($B:$B,J203) -> 3 | I203: =IF(H203=N203,"〇","×") -> 〇 | J203: S10160 | K203: 大府月見校 | L203: Obutsukimi | M203: 月見校 | N203: 3 | O203: S10160
B204: S10168 | C204: 長良校 | D204: Room8 | E204: 13 | F204: 3F2番 | H204: =COUNTIF($B:$B,J204) -> 5 | I204: =IF(H204=N204,"〇","×") -> 〇 | J204: S10170 | K204: 笠松校 | L204: Kasamatsu | M204: 笠松校 | N204: 5 | O204: S10170
B205: S10168 | C205: 長良校 | D205: Room9 | E205: 12 | F205: 3F3番 | H205: =COUNTIF($B:$B,J205) -> 5 | J205: S10171 | K205: 那加校
B206: S10168 | C206: 長良校 | D206: Room10 | E206: 20 | F206: 3F4番 | H206: =COUNTIF($B:$B,J206) -> 5 | J206: S10174 | K206: 岐阜予備
B207: S10168 | C207: 長良校 | D207: Room11 | E207: 24 | F207: 3F5番
B208: S10168 | C208: 長良校 | D208: Room12 | E208: 7 | F208: 4F北
...

Sheet きたん校舎20250923浪上部長情報
A1: 校舎名 | B1: No | C1: 机数 | D1: 教室名 | E1: ブランド→ | F1: アン | G1: そろ | H1: 習字 | I1: さんこく | J1: プログラミング | K1: ガクセン | L1: 光の泉 | M1: 本科 | N1: 山の手 | O1: キタン文理 | P1: 附小サクセス
A2: 光の泉本校・岐阜駅南口校 | B2: 教室1 | C2: 7 | D2: 1F | E2: 長机 | F2: ● | G2: ● | H2: ● | L2: ●
A3: 光の泉本校・岐阜駅南口校 | B3: 教室2 | C3: 2 | D3: 2F① | N3: ●
A4: 光の泉本校・岐阜駅南口校 | B4: 教室3 | C4: 2 | D4: 2F② | N4: ●
A5: 光の泉本校・岐阜駅南口校 | B5: 教室4 | C5: 2 | D5: 2F③ | N5: ●
A6: 光の泉本校・岐阜駅南口校 | B6: 教室5 | C6: 24 | D6: 2Fオープン | N6: ● | P6: ●
A7: 光の泉本校・岐阜駅南口校 | B7: 教室6 | C7: 8 | D7: 3F | Q7: 別会社
A8: 光の泉本校・岐阜駅南口校 | B8: 教室7 | C8: 20 | D8: 4F-1 | F8: ● | J8: ● | L8: ●
A9: 光の泉本校・岐阜駅南口校 | B9: 教室8 | C9: 15 | D9: 4F-2 | L9: ●
A10: 光の泉本校・岐阜駅南口校 | B10: 教室9 | C10: 18 | D10: 5F-1 | I10: ● | K10: ●
A11: 光の泉本校・岐阜駅南口校 | B11: 教室10 | C11: 35 | D11: 5F-2 | I11: ● | K11: ●
A12: 光の泉本校・岐阜駅南口校 | B12: 教室11 | C12: 10 | D12: 5F-4 | I12: ● | K12: ●
A13: 光の泉本校・岐阜駅南口校 | B13: 教室12 | C13: 31 | D13: 6F-1 | L13: ●
A14: 光の泉本校・岐阜駅南口校 | B14: 教室13 | C14: 8 | D14: 6F-2 | L14: ●
A15: 長良校・光の泉北校 | B15: 教室1 | C15: 17 | D15: 2F奥 | O15: ●
A16: 長良校・光の泉北校 | B16: 教室2 | C16: 14 | D16: 2Fオープン | O16: ●
A17: 長良校・光の泉北校 | B17: 教室3 | C17: 10 | D17: 2F旧アニー部屋 | F17: ● | J17: ●
A18: 長良校・光の泉北校 | B18: 教室4 | C18: 31 | D18: 2F自習ブース | O18: ●
A19: 長良校・光の泉北校 | B19: 教室5 | C19: 2 | D19: 2F山の手① | N19: ●
A20: 長良校・光の泉北校 | B20: 教室6 | C20: 4 | D20: 高校個別 | O20: ●
A21: 長良校・光の泉北校 | B21: 教室7 | C21: 22 | D21: 3F1番 | M21: ●
A22: 長良校・光の泉北校 | B22: 教室8 | C22: 13 | D22: 3F2番(自習ブース) | M22: ●
A23: 長良校・光の泉北校 | B23: 教室9 | C23: 12 | D23: 3F3番 | M23: ●
A24: 長良校・光の泉北校 | B24: 教室10 | C24: 20 | D24: 3F4番 | G24: ● | H24: ● | M24: ●
A25: 長良校・光の泉北校 | B25: 教室11 | C25: 24 | D25: 3F5番 | K25: ●
A26: 長良校・光の泉北校 | B26: 教室12 | C26: 7 | D26: 4F北 | I26: ● | L26: ●
A27: 長良校・光の泉北校 | B27: 教室13 | C27: 14 | D27: 4F真ん中 | I27: ● | L27: ●
A28: 長良校・光の泉北校 | B28: 教室14 | C28: 6 | D28: 4F南 | I28: ● | L28: ●
A29: 笠松校 | B29: 教室1 | C29: 34 | D29: 大教室 | F29: ● | I29: ● | J29: ● | M29: ●
A30: 笠松校 | B30: 教室2 | C30: 18 | D30: 小教室 | G30: ● | H30: ● | I30: ● | M30: ●
A31: 笠松校 | B31: 教室3 | C31: 11 | D31: オープン | G31: ● | H31: ● | I31: ● | M31: ●
A32: 笠松校 | B32: 教室4 | C32: 16 | D32: ガクセン | K32: ●
A33: 笠松校 | B33: 教室5 | C33: 14 | D33: 自習ブース | K33: ● | M33: ●
A34: 那加校 | B34: 教室1 | C34: 6 | D34: 1F手前 | F34: ● | J34: ●
A35: 那加校 | B35: 教室2 | C35: 21 | D35: 1F奥 | G35: ● | H35: ●
A36: 那加校 | B36: 教室3 | C36: 14 | D36: 2F左手前 | I36: ● | J36: ● | K36: ● | M36: ●
A37: 那加校 | B37: 教室4 | C37: 20 | D37: 2F左奥 | I37: ● | J37: ● | K37: ● | M37: ●
A38: 那加校 | B38: 教室5 | C38: 12 | D38: 2F右奥 | I38: ● | J38: ● | K38: ● | M38: ●
A39: 三里校 | B39: 教室1 | C39: 12 | D39: 奥 | M39: ●
A40: 三里校 | B40: 教室2 | C40: 10 | D40: 真ん中 | F40: ● | G40: ● | H40: ● | M40: ● | O40: ●
...
